Workbook

Sheet Assumptions
B1: MemoryCharm Financial Model — Assumptions
B2: Yellow cells are editable — change them to see impact on Projections & Summary sheets
B4: CHARM PRICING (Retail to Consumer)
B5: Tier | C5: Unit Price | D5: COGS / Unit | E5: Gross Margin
B6: 10-Year Charm | C6: 29.99 | D6: 8.5 | E6: =C6-D6 -> 21.49
B7: 15-Year Charm | C7: 44.99 | D7: 8.5 | E7: =C7-D7 -> 36.49
B8: Retail (Perpetual) Charm | C8: 69.99 | D8: 9 | E8: =C8-D8 -> 60.99
B10: UPSELL / ADD-ON PRICING
B11: Product | C11: Price | D11: Cost | E11: Margin
B12: Extend Memory (+5 years) | C12: 14.99 | D12: 1 | E12: =C12-D12 -> 13.99
B13: Upgrade Tier (avg revenue per upgrade) | C13: 19.99 | D13: 0.5 | E13: =C13-D13 -> 19.49
B14: Gift Wrap | C14: 4.99 | D14: 1.5 | E14: =C14-D14 -> 3.49
B16: MONTHLY UNIT SALES (Starting Month 1)
B17: Item | C17: Units / Month | D17: MoM Growth %
B18: 10-Year Charms | C18: 100 | D18: 0.08
B19: 15-Year Charms | C19: 40 | D19: 0.1
B20: Retail (Perpetual) Charms | C20: 15 | D20: 0.12
B22: UPSELL ATTACH RATES
B23: Extend Memory (monthly % of cumulative base) | C23: 0.02 | D23: Applied to cumulative charms sold
B24: Upgrade Tier (monthly % of cumulative base) | C24: 0.01
B25: Gift Wrap (% of new monthly charm sales) | C25: 0.15
B27: CONTENT SIZE ASSUMPTIONS | F27: API enforces 150 MB max per charm
B28: Media Type | C28: Avg Size (MB) | D28: % of Charms | E28: Weighted MB | F28: Weighted MB = Size x Mix %
B29: Video charms (single mp4/webm/mov) | C29: 55 | D29: 0.55 | E29: =C29*D29 -> 30.25 | F29: iPhone 1080p: HEVC ~20MB, H.264 ~65MB, 4K ~67MB for 30s
B30: Image gallery charms (1-20 images) | C30: 15 | D30: 0.35 | E30: =C30*D30 -> 5.25 | F30: ~4-6 iPhone photos avg at 2.5-4 MB each (HEIF/JPEG)
B31: Audio charms (single mp3/wav/ogg/aac) | C31: 6 | D31: 0.1 | E31: =C31*D31 -> 0.6 | F31: Voice message or song clip, 1-3 min
B32: Mix total (should = 100%) | D32: =D29+D30+D31 -> 1
B33: WEIGHTED AVG CONTENT SIZE (MB per charm) | C33: =E29+E30+E31 -> 36.1 | F33: Used for all storage cost calculations below
B34: Charm claim rate (% sold that get activated) | C34: 0.85 | F34: Unclaimed charms use zero storage
B35: Re-upload rate (% charms re-uploaded in 14-day settling) | C35: 0.2 | F35: Each re-upload = delete old + write new (extra ops)
B37: PLAYBACK & API REQUEST VOLUME
B38: Avg views per charm per month (first 3 months) | C38: 8 | F38: Novelty period — owner + shared views
B39: Avg views per charm per month (after 3 months) | C39: 2 | F39: Long-tail: occasional revisits
B40: % of views requiring glyph verification | C40: 0.4 | F40: Each glyph verify = 1 extra API call + Table write
B41: API CALLS PER CHARM LIFECYCLE (one-time) | C41: 5 | F41: claim + configure + get-upload-urls + finalize + owner-preview
B42: Table Storage writes per charm setup | C42: 8 | F42: charm entity + user-charm + profile + request log (sampled)
B43: Table Storage reads per charm view | C43: 3 | F43: GetCharm (entity lookup + rate-limit check + request log)
B45: AZURE BLOB STORAGE — COOL TIER (Backup) | F45: Azure is backup; R2 is primary CDN delivery
B46: Cost Component | C46: Rate | D46: Unit
B47: Storage (per GB per month) | C47: 0.01 | D47: $/GB/month | F47: Cool tier — $0.01/GB. Cold = $0.0036 (higher access)
...

Sheet 24-Month Projections
B1: MemoryCharm — 24-Month Financial Projections
B2: All values driven by Assumptions sheet — change inputs there
C4: Month 1 | D4: Month 2 | E4: Month 3 | F4: Month 4 | G4: Month 5 | H4: Month 6 | I4: Month 7 | J4: Month 8 | K4: Month 9 | L4: Month 10 | M4: Month 11 | N4: Month 12 | O4: Month 13 | P4: Month 14 | Q4: Month 15 | R4: Month 16 | S4: Month 17 | T4: Month 18 | U4: Month 19 | V4: Month 20 | W4: Month 21 | X4: Month 22 | Y4: Month 23 | Z4: Month 24
B5: UNIT SALES
B6: 10-Year Charms Sold | C6: =Assumptions!C18 -> 100 | D6: =ROUND(C6*(1+Assumptions!D18),0) -> 108 | E6: =ROUND(D6*(1+Assumptions!D18),0) -> 117 | F6: =ROUND(E6*(1+Assumptions!D18),0) -> 126 | G6: =ROUND(F6*(1+Assumptions!D18),0) -> 136 | H6: =ROUND(G6*(1+Assumptions!D18),0) -> 147 | I6: =ROUND(H6*(1+Assumptions!D18),0) -> 159 | J6: =ROUND(I6*(1+Assumptions!D18),0) -> 172 | K6: =ROUND(J6*(1+Assumptions!D18),0) -> 186 | L6: =ROUND(K6*(1+Assumptions!D18),0) -> 201 | M6: =ROUND(L6*(1+Assumptions!D18),0) -> 217 | N6: =ROUND(M6*(1+Assumptions!D18),0) -> 234 | O6: =ROUND(N6*(1+Assumptions!D18),0) -> 253 | P6: =ROUND(O6*(1+Assumptions!D18),0) -> 273 | Q6: =ROUND(P6*(1+Assumptions!D18),0) -> 295 | R6: =ROUND(Q6*(1+Assumptions!D18),0) -> 319 | S6: =ROUND(R6*(1+Assumptions!D18),0) -> 345 | T6: =ROUND(S6*(1+Assumptions!D18),0) -> 373 | U6: =ROUND(T6*(1+Assumptions!D18),0) -> 403 | V6: =ROUND(U6*(1+Assumptions!D18),0) -> 435 | W6: =ROUND(V6*(1+Assumptions!D18),0) -> 470 | X6: =ROUND(W6*(1+Assumptions!D18),0) -> 508 | Y6: =ROUND(X6*(1+Assumptions!D18),0) -> 549 | Z6: =ROUND(Y6*(1+Assumptions!D18),0) -> 593
B7: 15-Year Charms Sold | C7: =Assumptions!C19 -> 40 | D7: =ROUND(C7*(1+Assumptions!D19),0) -> 44 | E7: =ROUND(D7*(1+Assumptions!D19),0) -> 48 | F7: =ROUND(E7*(1+Assumptions!D19),0) -> 53 | G7: =ROUND(F7*(1+Assumptions!D19),0) -> 58 | H7: =ROUND(G7*(1+Assumptions!D19),0) -> 64 | I7: =ROUND(H7*(1+Assumptions!D19),0) -> 70 | J7: =ROUND(I7*(1+Assumptions!D19),0) -> 77 | K7: =ROUND(J7*(1+Assumptions!D19),0) -> 85 | L7: =ROUND(K7*(1+Assumptions!D19),0) -> 94 | M7: =ROUND(L7*(1+Assumptions!D19),0) -> 103 | N7: =ROUND(M7*(1+Assumptions!D19),0) -> 113 | O7: =ROUND(N7*(1+Assumptions!D19),0) -> 124 | P7: =ROUND(O7*(1+Assumptions!D19),0) -> 136 | Q7: =ROUND(P7*(1+Assumptions!D19),0) -> 150 | R7: =ROUND(Q7*(1+Assumptions!D19),0) -> 165 | S7: =ROUND(R7*(1+Assumptions!D19),0) -> 182 | T7: =ROUND(S7*(1+Assumptions!D19),0) -> 200 | U7: =ROUND(T7*(1+Assumptions!D19),0) -> 220 | V7: =ROUND(U7*(1+Assumptions!D19),0) -> 242 | W7: =ROUND(V7*(1+Assumptions!D19),0) -> 266 | X7: =ROUND(W7*(1+Assumptions!D19),0) -> 293 | Y7: =ROUND(X7*(1+Assumptions!D19),0) -> 322 | Z7: =ROUND(Y7*(1+Assumptions!D19),0) -> 354
B8: Retail (Perpetual) Charms Sold | C8: =Assumptions!C20 -> 15 | D8: =ROUND(C8*(1+Assumptions!D20),0) -> 17 | E8: =ROUND(D8*(1+Assumptions!D20),0) -> 19 | F8: =ROUND(E8*(1+Assumptions!D20),0) -> 21 | G8: =ROUND(F8*(1+Assumptions!D20),0) -> 24 | H8: =ROUND(G8*(1+Assumptions!D20),0) -> 27 | I8: =ROUND(H8*(1+Assumptions!D20),0) -> 30 | J8: =ROUND(I8*(1+Assumptions!D20),0) -> 34 | K8: =ROUND(J8*(1+Assumptions!D20),0) -> 38 | L8: =ROUND(K8*(1+Assumptions!D20),0) -> 43 | M8: =ROUND(L8*(1+Assumptions!D20),0) -> 48 | N8: =ROUND(M8*(1+Assumptions!D20),0) -> 54 | O8: =ROUND(N8*(1+Assumptions!D20),0) -> 60 | P8: =ROUND(O8*(1+Assumptions!D20),0) -> 67 | Q8: =ROUND(P8*(1+Assumptions!D20),0) -> 75 | R8: =ROUND(Q8*(1+Assumptions!D20),0) -> 84 | S8: =ROUND(R8*(1+Assumptions!D20),0) -> 94 | T8: =ROUND(S8*(1+Assumptions!D20),0) -> 105 | U8: =ROUND(T8*(1+Assumptions!D20),0) -> 118 | V8: =ROUND(U8*(1+Assumptions!D20),0) -> 132 | W8: =ROUND(V8*(1+Assumptions!D20),0) -> 148 | X8: =ROUND(W8*(1+Assumptions!D20),0) -> 166 | Y8: =ROUND(X8*(1+Assumptions!D20),0) -> 186 | Z8: =ROUND(Y8*(1+Assumptions!D20),0) -> 208
B9: Total Charms Sold (Month) | C9: =C6+C7+C8 -> 155 | D9: =D6+D7+D8 -> 169 | E9: =E6+E7+E8 -> 184 | F9: =F6+F7+F8 -> 200 | G9: =G6+G7+G8 -> 218 | H9: =H6+H7+H8 -> 238 | I9: =I6+I7+I8 -> 259 | J9: =J6+J7+J8 -> 283 | ... Z9: =Z6+Z7+Z8 -> 1155
B10: Cumulative Charms Sold | C10: =C9 -> 155 | D10: =C10+D9 -> 324 | E10: =D10+E9 -> 508 | F10: =E10+F9 -> 708 | G10: =F10+G9 -> 926 | H10: =G10+H9 -> 1164 | I10: =H10+I9 -> 1423 | J10: =I10+J9 -> 1706 | K10: =J10+K9 -> 2015 | ... Z10: =Y10+Z9 -> 12035
B11: Active Charms (claimed, storing content) | C11: =ROUND(C10*Assumptions!C34,0) -> 132 | D11: =ROUND(D10*Assumptions!C34,0) -> 275 | E11: =ROUND(E10*Assumptions!C34,0) -> 432 | F11: =ROUND(F10*Assumptions!C34,0) -> 602 | G11: =ROUND(G10*Assumptions!C34,0) -> 787 | H11: =ROUND(H10*Assumptions!C34,0) -> 989 | I11: =ROUND(I10*Assumptions!C34,0) -> 1210 | J11: =ROUND(J10*Assumptions!C34,0) -> 1450 | K11: =ROUND(K10*Assumptions!C34,0) -> 1713 | L11: =ROUND(L10*Assumptions!C34,0) -> 2000 | M11: =ROUND(M10*Assumptions!C34,0) -> 2313 | N11: =ROUND(N10*Assumptions!C34,0) -> 2654 | O11: =ROUND(O10*Assumptions!C34,0) -> 3025 | P11: =ROUND(P10*Assumptions!C34,0) -> 3430 | Q11: =ROUND(Q10*Assumptions!C34,0) -> 3872 | R11: =ROUND(R10*Assumptions!C34,0) -> 4355 | S11: =ROUND(S10*Assumptions!C34,0) -> 4882 | T11: =ROUND(T10*Assumptions!C34,0) -> 5459 | U11: =ROUND(U10*Assumptions!C34,0) -> 6089 | V11: =ROUND(V10*Assumptions!C34,0) -> 6776 | W11: =ROUND(W10*Assumptions!C34,0) -> 7528 | X11: =ROUND(X10*Assumptions!C34,0) -> 8350 | Y11: =ROUND(Y10*Assumptions!C34,0) -> 9248 | Z11: =ROUND(Z10*Assumptions!C34,0) -> 10230
B13: STORAGE VOLUME
B14: New Content Uploaded (GB) | C14: =ROUND(C9*Assumptions!C34*Assumptions!C33/1024,2) -> 4.64 | D14: =ROUND(D9*Assumptions!C34*Assumptions!C33/1024,2) -> 5.06 | E14: =ROUND(E9*Assumptions!C34*Assumptions!C33/1024,2) -> 5.51 | F14: =ROUND(F9*Assumptions!C34*Assumptions!C33/1024,2) -> 5.99 | G14: =ROUND(G9*Assumptions!C34*Assumptions!C33/1024,2) -> 6.53 | H14: =ROUND(H9*Assumptions!C34*Assumptions!C33/1024,2) -> 7.13 | I14: =ROUND(I9*Assumptions!C34*Assumptions!C33/1024,2) -> 7.76 | J14: =ROUND(J9*Assumptions!C34*Assumptions!C33/1024,2) -> 8.48 | K14: =ROUND(K9*Assumptions!C34*Assumptions!C33/1024,2) -> 9.26 | L14: =ROUND(L9*Assumptions!C34*Assumptions!C33/1024,2) -> 10.13 | M14: =ROUND(M9*Assumptions!C34*Assumptions!C33/1024,2) -> 11.03 | N14: =ROUND(N9*Assumptions!C34*Assumptions!C33/1024,2) -> 12.02 | O14: =ROUND(O9*Assumptions!C34*Assumptions!C33/1024,2) -> 13.1 | P14: =ROUND(P9*Assumptions!C34*Assumptions!C33/1024,2) -> 14.26 | Q14: =ROUND(Q9*Assumptions!C34*Assumptions!C33/1024,2) -> 15.58 | R14: =ROUND(R9*Assumptions!C34*Assumptions!C33/1024,2) -> 17.02 | S14: =ROUND(S9*Assumptions!C34*Assumptions!C33/1024,2) -> 18.61 | T14: =ROUND(T9*Assumptions!C34*Assumptions!C33/1024,2) -> 20.32 | U14: =ROUND(U9*Assumptions!C34*Assumptions!C33/1024,2) -> 22.2 | V14: =ROUND(V9*Assumptions!C34*Assumptions!C33/1024,2) -> 24.24 | W14: =ROUND(W9*Assumptions!C34*Assumptions!C33/1024,2) -> 26.49 | X14: =ROUND(X9*Assumptions!C34*Assumptions!C33/1024,2) -> 28.98 | Y14: =ROUND(Y9*Assumptions!C34*Assumptions!C33/1024,2) -> 31.67 | Z14: =ROUND(Z9*Assumptions!C34*Assumptions!C33/1024,2) -> 34.61
B15: Cumulative Content Stored (GB) | C15: =C14 -> 4.64 | D15: =C15+D14 -> 9.7 | E15: =D15+E14 -> 15.21 | F15: =E15+F14 -> 21.2 | G15: =F15+G14 -> 27.73 | H15: =G15+H14 -> 34.86 | I15: =H15+I14 -> 42.62 | J15: =I15+J14 -> 51.1 | K15: =J15+K14 -> 60.36 | ... Z15: =Y15+Z14 -> 360.62
B16: Cloudflare R2 Storage (GB) | C16: =C15 -> 4.64 | D16: =D15 -> 9.7 | E16: =E15 -> 15.21 | F16: =F15 -> 21.2 | G16: =G15 -> 27.73 | H16: =H15 -> 34.86 | I16: =I15 -> 42.62 | J16: =J15 -> 51.1 | ... Z16: =Z15 -> 360.62
B17: Azure Blob Cool Storage (GB) | C17: =C15 -> 4.64 | D17: =D15 -> 9.7 | E17: =E15 -> 15.21 | F17: =F15 -> 21.2 | G17: =G15 -> 27.73 | H17: =H15 -> 34.86 | I17: =I15 -> 42.62 | J17: =J15 -> 51.1 | ... Z17: =Z15 -> 360.62
B19: API & STORAGE REQUEST VOLUME
B20: Total Charm Playback Views (month) | C20: =ROUND(C9*Assumptions!C38+MAX(0,C11-C9)*Assumptions!C39,0) -> 1240 | D20: =ROUND((D9+C9)*Assumptions!C38+MAX(0,D11-(D9+C9))*Assumptions!C39,0) -> 2592 | E20: =ROUND((E9+D9+C9)*Assumptions!C38+MAX(0,E11-(E9+D9+C9))*Assumptions!C39,0) -> 4064 | F20: =ROUND((F9+E9+D9)*Assumptions!C38+MAX(0,F11-(F9+E9+D9))*Assumptions!C39,0) -> 4522 | G20: =ROUND((G9+F9+E9)*Assumptions!C38+MAX(0,G11-(G9+F9+E9))*Assumptions!C39,0) -> 5186 | H20: =ROUND((H9+G9+F9)*Assumptions!C38+MAX(0,H11-(H9+G9+F9))*Assumptions!C39,0) -> 5914 | I20: =ROUND((I9+H9+G9)*Assumptions!C38+MAX(0,I11-(I9+H9+G9))*Assumptions!C39,0) -> 6710 | J20: =ROUND((J9+I9+H9)*Assumptions!C38+MAX(0,J11-(J9+I9+H9))*Assumptions!C39,0) -> 7580 | K20: =ROUND((K9+J9+I9)*Assumptions!C38+MAX(0,K11-(K9+J9+I9))*Assumptions!C39,0) -> 8532 | L20: =ROUND((L9+K9+J9)*Assumptions!C38+MAX(0,L11-(L9+K9+J9))*Assumptions!C39,0) -> 9580 | M20: =ROUND((M9+L9+K9)*Assumptions!C38+MAX(0,M11-(M9+L9+K9))*Assumptions!C39,0) -> 10716 | N20: =ROUND((N9+M9+L9)*Assumptions!C38+MAX(0,N11-(N9+M9+L9))*Assumptions!C39,0) -> 11950 | O20: =ROUND((O9+N9+M9)*Assumptions!C38+MAX(0,O11-(O9+N9+M9))*Assumptions!C39,0) -> 13286 | P20: =ROUND((P9+O9+N9)*Assumptions!C38+MAX(0,P11-(P9+O9+N9))*Assumptions!C39,0) -> 14744 | Q20: =ROUND((Q9+P9+O9)*Assumptions!C38+MAX(0,Q11-(Q9+P9+O9))*Assumptions!C39,0) -> 16342 | R20: =ROUND((R9+Q9+P9)*Assumptions!C38+MAX(0,R11-(R9+Q9+P9))*Assumptions!C39,0) -> 18094 | S20: =ROUND((S9+R9+Q9)*Assumptions!C38+MAX(0,S11-(S9+R9+Q9))*Assumptions!C39,0) -> 20018 | T20: =ROUND((T9+S9+R9)*Assumptions!C38+MAX(0,T11-(T9+S9+R9))*Assumptions!C39,0) -> 22120 | U20: =ROUND((U9+T9+S9)*Assumptions!C38+MAX(0,U11-(U9+T9+S9))*Assumptions!C39,0) -> 24418 | V20: =ROUND((V9+U9+T9)*Assumptions!C38+MAX(0,V11-(V9+U9+T9))*Assumptions!C39,0) -> 26920 | W20: =ROUND((W9+V9+U9)*Assumptions!C38+MAX(0,W11-(W9+V9+U9))*Assumptions!C39,0) -> 29660 | X20: =ROUND((X9+W9+V9)*Assumptions!C38+MAX(0,X11-(X9+W9+V9))*Assumptions!C39,0) -> 32660 | Y20: =ROUND((Y9+X9+W9)*Assumptions!C38+MAX(0,Y11-(Y9+X9+W9))*Assumptions!C39,0) -> 35944 | Z20: =ROUND((Z9+Y9+X9)*Assumptions!C38+MAX(0,Z11-(Z9+Y9+X9))*Assumptions!C39,0) -> 39534
B21: Glyph Verification API Calls | C21: =ROUND(C20*Assumptions!C40,0) -> 496 | D21: =ROUND(D20*Assumptions!C40,0) -> 1037 | E21: =ROUND(E20*Assumptions!C40,0) -> 1626 | F21: =ROUND(F20*Assumptions!C40,0) -> 1809 | G21: =ROUND(G20*Assumptions!C40,0) -> 2074 | H21: =ROUND(H20*Assumptions!C40,0) -> 2366 | I21: =ROUND(I20*Assumptions!C40,0) -> 2684 | J21: =ROUND(J20*Assumptions!C40,0) -> 3032 | K21: =ROUND(K20*Assumptions!C40,0) -> 3413 | L21: =ROUND(L20*Assumptions!C40,0) -> 3832 | M21: =ROUND(M20*Assumptions!C40,0) -> 4286 | N21: =ROUND(N20*Assumptions!C40,0) -> 4780 | O21: =ROUND(O20*Assumptions!C40,0) -> 5314 | P21: =ROUND(P20*Assumptions!C40,0) -> 5898 | Q21: =ROUND(Q20*Assumptions!C40,0) -> 6537 | R21: =ROUND(R20*Assumptions!C40,0) -> 7238 | S21: =ROUND(S20*Assumptions!C40,0) -> 8007 | T21: =ROUND(T20*Assumptions!C40,0) -> 8848 | U21: =ROUND(U20*Assumptions!C40,0) -> 9767 | V21: =ROUND(V20*Assumptions!C40,0) -> 10768 | W21: =ROUND(W20*Assumptions!C40,0) -> 11864 | X21: =ROUND(X20*Assumptions!C40,0) -> 13064 | Y21: =ROUND(Y20*Assumptions!C40,0) -> 14378 | Z21: =ROUND(Z20*Assumptions!C40,0) -> 15814
B22: Total Azure Functions Invocations | C22: =ROUND((C9*Assumptions!C34*Assumptions!C41)+C20+C21+(C20*0.02),0) -> 2420 | D22: =ROUND((D9*Assumptions!C34*Assumptions!C41)+D20+D21+(D20*0.02),0) -> 4399 | E22: =ROUND((E9*Assumptions!C34*Assumptions!C41)+E20+E21+(E20*0.02),0) -> 6553 | F22: =ROUND((F9*Assumptions!C34*Assumptions!C41)+F20+F21+(F20*0.02),0) -> 7271 | G22: =ROUND((G9*Assumptions!C34*Assumptions!C41)+G20+G21+(G20*0.02),0) -> 8290 | H22: =ROUND((H9*Assumptions!C34*Assumptions!C41)+H20+H21+(H20*0.02),0) -> 9410 | I22: =ROUND((I9*Assumptions!C34*Assumptions!C41)+I20+I21+(I20*0.02),0) -> 10629 | J22: =ROUND((J9*Assumptions!C34*Assumptions!C41)+J20+J21+(J20*0.02),0) -> 11966 | K22: =ROUND((K9*Assumptions!C34*Assumptions!C41)+K20+K21+(K20*0.02),0) -> 13429 | L22: =ROUND((L9*Assumptions!C34*Assumptions!C41)+L20+L21+(L20*0.02),0) -> 15040 | M22: =ROUND((M9*Assumptions!C34*Assumptions!C41)+M20+M21+(M20*0.02),0) -> 16780 | N22: =ROUND((N9*Assumptions!C34*Assumptions!C41)+N20+N21+(N20*0.02),0) -> 18673 | O22: =ROUND((O9*Assumptions!C34*Assumptions!C41)+O20+O21+(O20*0.02),0) -> 20723 | P22: =ROUND((P9*Assumptions!C34*Assumptions!C41)+P20+P21+(P20*0.02),0) -> 22960 | Q22: =ROUND((Q9*Assumptions!C34*Assumptions!C41)+Q20+Q21+(Q20*0.02),0) -> 25416 | R22: =ROUND((R9*Assumptions!C34*Assumptions!C41)+R20+R21+(R20*0.02),0) -> 28108 | S22: =ROUND((S9*Assumptions!C34*Assumptions!C41)+S20+S21+(S20*0.02),0) -> 31065 | T22: =ROUND((T9*Assumptions!C34*Assumptions!C41)+T20+T21+(T20*0.02),0) -> 34292 | U22: =ROUND((U9*Assumptions!C34*Assumptions!C41)+U20+U21+(U20*0.02),0) -> 37823 | V22: =ROUND((V9*Assumptions!C34*Assumptions!C41)+V20+V21+(V20*0.02),0) -> 41665 | W22: =ROUND((W9*Assumptions!C34*Assumptions!C41)+W20+W21+(W20*0.02),0) -> 45874 | X22: =ROUND((X9*Assumptions!C34*Assumptions!C41)+X20+X21+(X20*0.02),0) -> 50487 | Y22: =ROUND((Y9*Assumptions!C34*Assumptions!C41)+Y20+Y21+(Y20*0.02),0) -> 55533 | Z22: =ROUND((Z9*Assumptions!C34*Assumptions!C41)+Z20+Z21+(Z20*0.02),0) -> 61047
B23: R2 Class A Ops (Writes) | C23: =ROUND(C9*Assumptions!C34*2*(1+Assumptions!C35),0) -> 316 | D23: =ROUND(D9*Assumptions!C34*2*(1+Assumptions!C35),0) -> 345 | E23: =ROUND(E9*Assumptions!C34*2*(1+Assumptions!C35),0) -> 375 | F23: =ROUND(F9*Assumptions!C34*2*(1+Assumptions!C35),0) -> 408 | G23: =ROUND(G9*Assumptions!C34*2*(1+Assumptions!C35),0) -> 445 | H23: =ROUND(H9*Assumptions!C34*2*(1+Assumptions!C35),0) -> 486 | I23: =ROUND(I9*Assumptions!C34*2*(1+Assumptions!C35),0) -> 528 | J23: =ROUND(J9*Assumptions!C34*2*(1+Assumptions!C35),0) -> 577 | K23: =ROUND(K9*Assumptions!C34*2*(1+Assumptions!C35),0) -> 630 | L23: =ROUND(L9*Assumptions!C34*2*(1+Assumptions!C35),0) -> 690 | M23: =ROUND(M9*Assumptions!C34*2*(1+Assumptions!C35),0) -> 751 | N23: =ROUND(N9*Assumptions!C34*2*(1+Assumptions!C35),0) -> 818 | O23: =ROUND(O9*Assumptions!C34*2*(1+Assumptions!C35),0) -> 891 | P23: =ROUND(P9*Assumptions!C34*2*(1+Assumptions!C35),0) -> 971 | Q23: =ROUND(Q9*Assumptions!C34*2*(1+Assumptions!C35),0) -> 1061 | R23: =ROUND(R9*Assumptions!C34*2*(1+Assumptions!C35),0) -> 1159 | S23: =ROUND(S9*Assumptions!C34*2*(1+Assumptions!C35),0) -> 1267 | T23: =ROUND(T9*Assumptions!C34*2*(1+Assumptions!C35),0) -> 1383 | U23: =ROUND(U9*Assumptions!C34*2*(1+Assumptions!C35),0) -> 1512 | V23: =ROUND(V9*Assumptions!C34*2*(1+Assumptions!C35),0) -> 1650 | W23: =ROUND(W9*Assumptions!C34*2*(1+Assumptions!C35),0) -> 1803 | X23: =ROUND(X9*Assumptions!C34*2*(1+Assumptions!C35),0) -> 1973 | Y23: =ROUND(Y9*Assumptions!C34*2*(1+Assumptions!C35),0) -> 2156 | Z23: =ROUND(Z9*Assumptions!C34*2*(1+Assumptions!C35),0) -> 2356
B24: R2 Class B Ops (Reads / Playback) | C24: =C20 -> 1240 | D24: =D20 -> 2592 | E24: =E20 -> 4064 | F24: =F20 -> 4522 | G24: =G20 -> 5186 | H24: =H20 -> 5914 | I24: =I20 -> 6710 | J24: =J20 -> 7580 | ... Z24: =Z20 -> 39534
B25: Azure Blob Write Ops (Backup Uploads) | C25: =C23 -> 316 | D25: =D23 -> 345 | E25: =E23 -> 375 | F25: =F23 -> 408 | G25: =G23 -> 445 | H25: =H23 -> 486 | I25: =I23 -> 528 | J25: =J23 -> 577 | ... Z25: =Z23 -> 2356
B26: Azure Blob Read Ops (Fallback — est 2%) | C26: =ROUND(C20*0.02,0) -> 25 | D26: =ROUND(D20*0.02,0) -> 52 | E26: =ROUND(E20*0.02,0) -> 81 | F26: =ROUND(F20*0.02,0) -> 90 | G26: =ROUND(G20*0.02,0) -> 104 | H26: =ROUND(H20*0.02,0) -> 118 | I26: =ROUND(I20*0.02,0) -> 134 | J26: =ROUND(J20*0.02,0) -> 152 | ... Z26: =ROUND(Z20*0.02,0) -> 791
B27: Azure Table Transactions (Total) | C27: =ROUND(C9*Assumptions!C34*Assumptions!C42+C20*Assumptions!C43+C21*2,0) -> 5766 | D27: =ROUND(D9*Assumptions!C34*Assumptions!C42+D20*Assumptions!C43+D21*2,0) -> 10999 | E27: =ROUND(E9*Assumptions!C34*Assumptions!C42+E20*Assumptions!C43+E21*2,0) -> 16695 | F27: =ROUND(F9*Assumptions!C34*Assumptions!C42+F20*Assumptions!C43+F21*2,0) -> 18544 | G27: =ROUND(G9*Assumptions!C34*Assumptions!C42+G20*Assumptions!C43+G21*2,0) -> 21188 | H27: =ROUND(H9*Assumptions!C34*Assumptions!C42+H20*Assumptions!C43+H21*2,0) -> 24092 | I27: =ROUND(I9*Assumptions!C34*Assumptions!C42+I20*Assumptions!C43+I21*2,0) -> 27259 | J27: =ROUND(J9*Assumptions!C34*Assumptions!C42+J20*Assumptions!C43+J21*2,0) -> 30728 | K27: =ROUND(K9*Assumptions!C34*Assumptions!C42+K20*Assumptions!C43+K21*2,0) -> 34523 | L27: =ROUND(L9*Assumptions!C34*Assumptions!C42+L20*Assumptions!C43+L21*2,0) -> 38702 | M27: =ROUND(M9*Assumptions!C34*Assumptions!C42+M20*Assumptions!C43+M21*2,0) -> 43222 | N27: =ROUND(N9*Assumptions!C34*Assumptions!C42+N20*Assumptions!C43+N21*2,0) -> 48137 | O27: =ROUND(O9*Assumptions!C34*Assumptions!C42+O20*Assumptions!C43+O21*2,0) -> 53458 | P27: =ROUND(P9*Assumptions!C34*Assumptions!C42+P20*Assumptions!C43+P21*2,0) -> 59265 | Q27: =ROUND(Q9*Assumptions!C34*Assumptions!C42+Q20*Assumptions!C43+Q21*2,0) -> 65636 | R27: =ROUND(R9*Assumptions!C34*Assumptions!C42+R20*Assumptions!C43+R21*2,0) -> 72620 | S27: =ROUND(S9*Assumptions!C34*Assumptions!C42+S20*Assumptions!C43+S21*2,0) -> 80291 | T27: =ROUND(T9*Assumptions!C34*Assumptions!C42+T20*Assumptions!C43+T21*2,0) -> 88666 | U27: =ROUND(U9*Assumptions!C34*Assumptions!C42+U20*Assumptions!C43+U21*2,0) -> 97827 | V27: =ROUND(V9*Assumptions!C34*Assumptions!C42+V20*Assumptions!C43+V21*2,0) -> 107797 | W27: =ROUND(W9*Assumptions!C34*Assumptions!C42+W20*Assumptions!C43+W21*2,0) -> 118719 | X27: =ROUND(X9*Assumptions!C34*Assumptions!C42+X20*Assumptions!C43+X21*2,0) -> 130684 | Y27: =ROUND(Y9*Assumptions!C34*Assumptions!C42+Y20*Assumptions!C43+Y21*2,0) -> 143776 | Z27: =ROUND(Z9*Assumptions!C34*Assumptions!C42+Z20*Assumptions!C43+Z21*2,0) -> 158084
B28: R2 Playback Bandwidth (GB) — FREE egress | C28: =ROUND(C20*Assumptions!C33/1024,1) -> 43.7 | D28: =ROUND(D20*Assumptions!C33/1024,1) -> 91.4 | E28: =ROUND(E20*Assumptions!C33/1024,1) -> 143.3 | F28: =ROUND(F20*Assumptions!C33/1024,1) -> 159.4 | G28: =ROUND(G20*Assumptions!C33/1024,1) -> 182.8 | H28: =ROUND(H20*Assumptions!C33/1024,1) -> 208.5 | I28: =ROUND(I20*Assumptions!C33/1024,1) -> 236.6 | J28: =ROUND(J20*Assumptions!C33/1024,1) -> 267.2 | K28: =ROUND(K20*Assumptions!C33/1024,1) -> 300.8 | L28: =ROUND(L20*Assumptions!C33/1024,1) -> 337.7 | M28: =ROUND(M20*Assumptions!C33/1024,1) -> 377.8 | N28: =ROUND(N20*Assumptions!C33/1024,1) -> 421.3 | O28: =ROUND(O20*Assumptions!C33/1024,1) -> 468.4 | P28: =ROUND(P20*Assumptions!C33/1024,1) -> 519.8 | Q28: =ROUND(Q20*Assumptions!C33/1024,1) -> 576.1 | R28: =ROUND(R20*Assumptions!C33/1024,1) -> 637.9 | S28: =ROUND(S20*Assumptions!C33/1024,1) -> 705.7 | T28: =ROUND(T20*Assumptions!C33/1024,1) -> 779.8 | U28: =ROUND(U20*Assumptions!C33/1024,1) -> 860.8 | V28: =ROUND(V20*Assumptions!C33/1024,1) -> 949 | W28: =ROUND(W20*Assumptions!C33/1024,1) -> 1045.6 | X28: =ROUND(X20*Assumptions!C33/1024,1) -> 1151.4 | Y28: =ROUND(Y20*Assumptions!C33/1024,1) -> 1267.2 | Z28: =ROUND(Z20*Assumptions!C33/1024,1) -> 1393.7
B30: INFRASTRUCTURE COST BREAKDOWN
B31: Azure Blob: Storage Cost | C31: =C17*Assumptions!C47 -> 0.0464 | D31: =D17*Assumptions!C47 -> 0.097 | E31: =E17*Assumptions!C47 -> 0.1521 | F31: =F17*Assumptions!C47 -> 0.212 | G31: =G17*Assumptions!C47 -> 0.2773 | H31: =H17*Assumptions!C47 -> 0.3486 | I31: =I17*Assumptions!C47 -> 0.4262 | J31: =J17*Assumptions!C47 -> 0.511 | K31: =K17*Assumptions!C47 -> 0.6036 | L31: =L17*Assumptions!C47 -> 0.7049 | M31: =M17*Assumptions!C47 -> 0.8152 | N31: =N17*Assumptions!C47 -> 0.9354 | O31: =O17*Assumptions!C47 -> 1.0664 | P31: =P17*Assumptions!C47 -> 1.209 | Q31: =Q17*Assumptions!C47 -> 1.3648 | R31: =R17*Assumptions!C47 -> 1.535 | S31: =S17*Assumptions!C47 -> 1.7211 | T31: =T17*Assumptions!C47 -> 1.9243 | U31: =U17*Assumptions!C47 -> 2.1463 | V31: =V17*Assumptions!C47 -> 2.3887 | W31: =W17*Assumptions!C47 -> 2.6536 | X31: =X17*Assumptions!C47 -> 2.9434 | Y31: =Y17*Assumptions!C47 -> 3.2601 | Z31: =Z17*Assumptions!C47 -> 3.6062
B32: Azure Blob: Write Operations | C32: =(C25/10000)*Assumptions!C48 -> 0.00316 | D32: =(D25/10000)*Assumptions!C48 -> 0.00345 | E32: =(E25/10000)*Assumptions!C48 -> 0.00375 | F32: =(F25/10000)*Assumptions!C48 -> 0.00408 | G32: =(G25/10000)*Assumptions!C48 -> 0.00445 | H32: =(H25/10000)*Assumptions!C48 -> 0.00486 | I32: =(I25/10000)*Assumptions!C48 -> 0.00528 | J32: =(J25/10000)*Assumptions!C48 -> 0.00577 | K32: =(K25/10000)*Assumptions!C48 -> 0.0063 | L32: =(L25/10000)*Assumptions!C48 -> 0.0069 | M32: =(M25/10000)*Assumptions!C48 -> 0.00751 | N32: =(N25/10000)*Assumptions!C48 -> 0.00818 | O32: =(O25/10000)*Assumptions!C48 -> 0.00891 | P32: =(P25/10000)*Assumptions!C48 -> 0.00971 | Q32: =(Q25/10000)*Assumptions!C48 -> 0.01061 | R32: =(R25/10000)*Assumptions!C48 -> 0.01159 | S32: =(S25/10000)*Assumptions!C48 -> 0.01267 | T32: =(T25/10000)*Assumptions!C48 -> 0.01383 | U32: =(U25/10000)*Assumptions!C48 -> 0.01512 | V32: =(V25/10000)*Assumptions!C48 -> 0.0165 | W32: =(W25/10000)*Assumptions!C48 -> 0.01803 | X32: =(X25/10000)*Assumptions!C48 -> 0.01973 | Y32: =(Y25/10000)*Assumptions!C48 -> 0.02156 | Z32: =(Z25/10000)*Assumptions!C48 -> 0.02356
B33: Azure Blob: Read Ops (Fallback) | C33: =(C26/10000)*Assumptions!C49 -> 2.5e-05 | D33: =(D26/10000)*Assumptions!C49 -> 5.2e-05 | E33: =(E26/10000)*Assumptions!C49 -> 8.1e-05 | F33: =(F26/10000)*Assumptions!C49 -> 9e-05 | G33: =(G26/10000)*Assumptions!C49 -> 0.000104 | H33: =(H26/10000)*Assumptions!C49 -> 0.000118 | I33: =(I26/10000)*Assumptions!C49 -> 0.000134 | J33: =(J26/10000)*Assumptions!C49 -> 0.000152 | K33: =(K26/10000)*Assumptions!C49 -> 0.000171 | L33: =(L26/10000)*Assumptions!C49 -> 0.000192 | M33: =(M26/10000)*Assumptions!C49 -> 0.000214 | N33: =(N26/10000)*Assumptions!C49 -> 0.000239 | O33: =(O26/10000)*Assumptions!C49 -> 0.000266 | P33: =(P26/10000)*Assumptions!C49 -> 0.000295 | Q33: =(Q26/10000)*Assumptions!C49 -> 0.000327 | R33: =(R26/10000)*Assumptions!C49 -> 0.000362 | S33: =(S26/10000)*Assumptions!C49 -> 0.0004 | T33: =(T26/10000)*Assumptions!C49 -> 0.000442 | U33: =(U26/10000)*Assumptions!C49 -> 0.000488 | V33: =(V26/10000)*Assumptions!C49 -> 0.000538 | W33: =(W26/10000)*Assumptions!C49 -> 0.000593 | X33: =(X26/10000)*Assumptions!C49 -> 0.000653 | Y33: =(Y26/10000)*Assumptions!C49 -> 0.000719 | Z33: =(Z26/10000)*Assumptions!C49 -> 0.000791
B34: Azure Blob: Data Retrieval (Fallback) | C34: =(C26*Assumptions!C33/1024)*Assumptions!C50 -> 0.0088134766 | D34: =(D26*Assumptions!C33/1024)*Assumptions!C50 -> 0.018332031 | E34: =(E26*Assumptions!C33/1024)*Assumptions!C50 -> 0.028555664 | F34: =(F26*Assumptions!C33/1024)*Assumptions!C50 -> 0.031728516 | G34: =(G26*Assumptions!C33/1024)*Assumptions!C50 -> 0.036664063 | H34: =(H26*Assumptions!C33/1024)*Assumptions!C50 -> 0.041599609 | I34: =(I26*Assumptions!C33/1024)*Assumptions!C50 -> 0.047240234 | J34: =(J26*Assumptions!C33/1024)*Assumptions!C50 -> 0.053585937 | K34: =(K26*Assumptions!C33/1024)*Assumptions!C50 -> 0.06028418 | L34: =(L26*Assumptions!C33/1024)*Assumptions!C50 -> 0.0676875 | M34: =(M26*Assumptions!C33/1024)*Assumptions!C50 -> 0.075443359 | N34: =(N26*Assumptions!C33/1024)*Assumptions!C50 -> 0.084256836 | O34: =(O26*Assumptions!C33/1024)*Assumptions!C50 -> 0.093775391 | P34: =(P26*Assumptions!C33/1024)*Assumptions!C50 -> 0.10399902 | Q34: =(Q26*Assumptions!C33/1024)*Assumptions!C50 -> 0.11528027 | R34: =(R26*Assumptions!C33/1024)*Assumptions!C50 -> 0.12761914 | S34: =(S26*Assumptions!C33/1024)*Assumptions!C50 -> 0.14101563 | T34: =(T26*Assumptions!C33/1024)*Assumptions!C50 -> 0.15582227 | U34: =(U26*Assumptions!C33/1024)*Assumptions!C50 -> 0.17203906 | V34: =(V26*Assumptions!C33/1024)*Assumptions!C50 -> 0.18966602 | W34: =(W26*Assumptions!C33/1024)*Assumptions!C50 -> 0.20905566 | X34: =(X26*Assumptions!C33/1024)*Assumptions!C50 -> 0.23020801 | Y34: =(Y26*Assumptions!C33/1024)*Assumptions!C50 -> 0.25347559 | Z34: =(Z26*Assumptions!C33/1024)*Assumptions!C50 -> 0.2788584
B35: Azure Blob Total | C35: =C31+C32+C33+C34 -> 0.058398477 | D35: =D31+D32+D33+D34 -> 0.11883403 | E35: =E31+E32+E33+E34 -> 0.18448666 | F35: =F31+F32+F33+F34 -> 0.24789852 | G35: =G31+G32+G33+G34 -> 0.31851806 | H35: =H31+H32+H33+H34 -> 0.39517761 | I35: =I31+I32+I33+I34 -> 0.47885423 | J35: =J31+J32+J33+J34 -> 0.57050794 | ... Z35: =Z31+Z32+Z33+Z34 -> 3.9094094
B36: R2: Storage Cost | C36: =MAX(0,C16-Assumptions!C59)*Assumptions!C55 -> 0 | D36: =MAX(0,D16-Assumptions!C59)*Assumptions!C55 -> 0 | E36: =MAX(0,E16-Assumptions!C59)*Assumptions!C55 -> 0.07815 | F36: =MAX(0,F16-Assumptions!C59)*Assumptions!C55 -> 0.168 | G36: =MAX(0,G16-Assumptions!C59)*Assumptions!C55 -> 0.26595 | H36: =MAX(0,H16-Assumptions!C59)*Assumptions!C55 -> 0.3729 | I36: =MAX(0,I16-Assumptions!C59)*Assumptions!C55 -> 0.4893 | J36: =MAX(0,J16-Assumptions!C59)*Assumptions!C55 -> 0.6165 | K36: =MAX(0,K16-Assumptions!C59)*Assumptions!C55 -> 0.7554 | L36: =MAX(0,L16-Assumptions!C59)*Assumptions!C55 -> 0.90735 | M36: =MAX(0,M16-Assumptions!C59)*Assumptions!C55 -> 1.0728 | N36: =MAX(0,N16-Assumptions!C59)*Assumptions!C55 -> 1.2531 | O36: =MAX(0,O16-Assumptions!C59)*Assumptions!C55 -> 1.4496 | P36: =MAX(0,P16-Assumptions!C59)*Assumptions!C55 -> 1.6635 | Q36: =MAX(0,Q16-Assumptions!C59)*Assumptions!C55 -> 1.8972 | R36: =MAX(0,R16-Assumptions!C59)*Assumptions!C55 -> 2.1525 | S36: =MAX(0,S16-Assumptions!C59)*Assumptions!C55 -> 2.43165 | T36: =MAX(0,T16-Assumptions!C59)*Assumptions!C55 -> 2.73645 | U36: =MAX(0,U16-Assumptions!C59)*Assumptions!C55 -> 3.06945 | V36: =MAX(0,V16-Assumptions!C59)*Assumptions!C55 -> 3.43305 | W36: =MAX(0,W16-Assumptions!C59)*Assumptions!C55 -> 3.8304 | X36: =MAX(0,X16-Assumptions!C59)*Assumptions!C55 -> 4.2651 | Y36: =MAX(0,Y16-Assumptions!C59)*Assumptions!C55 -> 4.74015 | Z36: =MAX(0,Z16-Assumptions!C59)*Assumptions!C55 -> 5.2593
B37: R2: Class A Ops (Writes) | C37: =MAX(0,C23-10000000)*Assumptions!C56/1000000 -> 0 | D37: =MAX(0,D23-10000000)*Assumptions!C56/1000000 -> 0 | E37: =MAX(0,E23-10000000)*Assumptions!C56/1000000 -> 0 | F37: =MAX(0,F23-10000000)*Assumptions!C56/1000000 -> 0 | G37: =MAX(0,G23-10000000)*Assumptions!C56/1000000 -> 0 | H37: =MAX(0,H23-10000000)*Assumptions!C56/1000000 -> 0 | I37: =MAX(0,I23-10000000)*Assumptions!C56/1000000 -> 0 | J37: =MAX(0,J23-10000000)*Assumptions!C56/1000000 -> 0 | K37: =MAX(0,K23-10000000)*Assumptions!C56/1000000 -> 0 | L37: =MAX(0,L23-10000000)*Assumptions!C56/1000000 -> 0 | M37: =MAX(0,M23-10000000)*Assumptions!C56/1000000 -> 0 | N37: =MAX(0,N23-10000000)*Assumptions!C56/1000000 -> 0 | O37: =MAX(0,O23-10000000)*Assumptions!C56/1000000 -> 0 | P37: =MAX(0,P23-10000000)*Assumptions!C56/1000000 -> 0 | Q37: =MAX(0,Q23-10000000)*Assumptions!C56/1000000 -> 0 | R37: =MAX(0,R23-10000000)*Assumptions!C56/1000000 -> 0 | S37: =MAX(0,S23-10000000)*Assumptions!C56/1000000 -> 0 | T37: =MAX(0,T23-10000000)*Assumptions!C56/1000000 -> 0 | U37: =MAX(0,U23-10000000)*Assumptions!C56/1000000 -> 0 | V37: =MAX(0,V23-10000000)*Assumptions!C56/1000000 -> 0 | W37: =MAX(0,W23-10000000)*Assumptions!C56/1000000 -> 0 | X37: =MAX(0,X23-10000000)*Assumptions!C56/1000000 -> 0 | Y37: =MAX(0,Y23-10000000)*Assumptions!C56/1000000 -> 0 | Z37: =MAX(0,Z23-10000000)*Assumptions!C56/1000000 -> 0
B38: R2: Class B Ops (Reads) | C38: =MAX(0,C24-10000000)*Assumptions!C57/1000000 -> 0 | D38: =MAX(0,D24-10000000)*Assumptions!C57/1000000 -> 0 | E38: =MAX(0,E24-10000000)*Assumptions!C57/1000000 -> 0 | F38: =MAX(0,F24-10000000)*Assumptions!C57/1000000 -> 0 | G38: =MAX(0,G24-10000000)*Assumptions!C57/1000000 -> 0 | H38: =MAX(0,H24-10000000)*Assumptions!C57/1000000 -> 0 | I38: =MAX(0,I24-10000000)*Assumptions!C57/1000000 -> 0 | J38: =MAX(0,J24-10000000)*Assumptions!C57/1000000 -> 0 | K38: =MAX(0,K24-10000000)*Assumptions!C57/1000000 -> 0 | L38: =MAX(0,L24-10000000)*Assumptions!C57/1000000 -> 0 | M38: =MAX(0,M24-10000000)*Assumptions!C57/1000000 -> 0 | N38: =MAX(0,N24-10000000)*Assumptions!C57/1000000 -> 0 | O38: =MAX(0,O24-10000000)*Assumptions!C57/1000000 -> 0 | P38: =MAX(0,P24-10000000)*Assumptions!C57/1000000 -> 0 | Q38: =MAX(0,Q24-10000000)*Assumptions!C57/1000000 -> 0 | R38: =MAX(0,R24-10000000)*Assumptions!C57/1000000 -> 0 | S38: =MAX(0,S24-10000000)*Assumptions!C57/1000000 -> 0 | T38: =MAX(0,T24-10000000)*Assumptions!C57/1000000 -> 0 | U38: =MAX(0,U24-10000000)*Assumptions!C57/1000000 -> 0 | V38: =MAX(0,V24-10000000)*Assumptions!C57/1000000 -> 0 | W38: =MAX(0,W24-10000000)*Assumptions!C57/1000000 -> 0 | X38: =MAX(0,X24-10000000)*Assumptions!C57/1000000 -> 0 | Y38: =MAX(0,Y24-10000000)*Assumptions!C57/1000000 -> 0 | Z38: =MAX(0,Z24-10000000)*Assumptions!C57/1000000 -> 0
B39: Cloudflare R2 Total | C39: =C36+C37+C38 -> 0 | D39: =D36+D37+D38 -> 0 | E39: =E36+E37+E38 -> 0.07815 | F39: =F36+F37+F38 -> 0.168 | G39: =G36+G37+G38 -> 0.26595 | H39: =H36+H37+H38 -> 0.3729 | I39: =I36+I37+I38 -> 0.4893 | J39: =J36+J37+J38 -> 0.6165 | ... Z39: =Z36+Z37+Z38 -> 5.2593
B40: Azure Table Storage | C40: =(C11*Assumptions!C65/1024/1024)*Assumptions!C63+(C27/10000)*Assumptions!C64 -> 0.00021890565 | D40: =(D11*Assumptions!C65/1024/1024)*Assumptions!C63+(D27/10000)*Assumptions!C64 -> 0.00041956744 | E40: =(E11*Assumptions!C65/1024/1024)*Assumptions!C63+(E27/10000)*Assumptions!C64 -> 0.00063809886 | F40: =(F11*Assumptions!C65/1024/1024)*Assumptions!C63+(F27/10000)*Assumptions!C64 -> 0.00071925407 | G40: =(G11*Assumptions!C65/1024/1024)*Assumptions!C63+(G27/10000)*Assumptions!C64 -> 0.00083031675 | H40: =(H11*Assumptions!C65/1024/1024)*Assumptions!C63+(H27/10000)*Assumptions!C64 -> 0.00095219855 | I40: =(I11*Assumptions!C65/1024/1024)*Assumptions!C63+(I27/10000)*Assumptions!C64 -> 0.0010851791 | J40: =(J11*Assumptions!C65/1024/1024)*Assumptions!C63+(J27/10000)*Assumptions!C64 -> 0.0012306625 | K40: =(K11*Assumptions!C65/1024/1024)*Assumptions!C63+(K27/10000)*Assumptions!C64 -> 0.001389856 | L40: =(L11*Assumptions!C65/1024/1024)*Assumptions!C63+(L27/10000)*Assumptions!C64 -> 0.0015649334 | M40: =(M11*Assumptions!C65/1024/1024)*Assumptions!C63+(M27/10000)*Assumptions!C64 -> 0.0017545184 | N40: =(N11*Assumptions!C65/1024/1024)*Assumptions!C63+(N27/10000)*Assumptions!C64 -> 0.0019607266 | O40: =(O11*Assumptions!C65/1024/1024)*Assumptions!C63+(O27/10000)*Assumptions!C64 -> 0.0021841258 | P40: =(P11*Assumptions!C65/1024/1024)*Assumptions!C63+(P27/10000)*Assumptions!C64 -> 0.0024279393 | Q40: =(Q11*Assumptions!C65/1024/1024)*Assumptions!C63+(Q27/10000)*Assumptions!C64 -> 0.0026952324 | R40: =(R11*Assumptions!C65/1024/1024)*Assumptions!C63+(R27/10000)*Assumptions!C64 -> 0.0029881126 | S40: =(S11*Assumptions!C65/1024/1024)*Assumptions!C63+(S27/10000)*Assumptions!C64 -> 0.0033095014 | T40: =(T11*Assumptions!C65/1024/1024)*Assumptions!C63+(T27/10000)*Assumptions!C64 -> 0.0036605257 | U40: =(U11*Assumptions!C65/1024/1024)*Assumptions!C63+(U27/10000)*Assumptions!C64 -> 0.0040443951 | V40: =(V11*Assumptions!C65/1024/1024)*Assumptions!C63+(V27/10000)*Assumptions!C64 -> 0.0044622807 | W40: =(W11*Assumptions!C65/1024/1024)*Assumptions!C63+(W27/10000)*Assumptions!C64 -> 0.0049200174 | X40: =(X11*Assumptions!C65/1024/1024)*Assumptions!C63+(X27/10000)*Assumptions!C64 -> 0.0054213102 | Y40: =(Y11*Assumptions!C65/1024/1024)*Assumptions!C63+(Y27/10000)*Assumptions!C64 -> 0.0059696982 | Z40: =(Z11*Assumptions!C65/1024/1024)*Assumptions!C63+(Z27/10000)*Assumptions!C64 -> 0.0065690719
B41: Azure Functions (Compute) | C41: =MAX(0,C22-Assumptions!C73)/1000000*Assumptions!C69+MAX(0,C22*(Assumptions!C71/1000)*(Assumptions!C72/1024)-Assumptions!C74)*Assumptions!C70 -> 0 | D41: =MAX(0,D22-Assumptions!C73)/1000000*Assumptions!C69+MAX(0,D22*(Assumptions!C71/1000)*(Assumptions!C72/1024)-Assumptions!C74)*Assumptions!C70 -> 0 | E41: =MAX(0,E22-Assumptions!C73)/1000000*Assumptions!C69+MAX(0,E22*(Assumptions!C71/1000)*(Assumptions!C72/1024)-Assumptions!C74)*Assumptions!C70 -> 0 | F41: =MAX(0,F22-Assumptions!C73)/1000000*Assumptions!C69+MAX(0,F22*(Assumptions!C71/1000)*(Assumptions!C72/1024)-Assumptions!C74)*Assumptions!C70 -> 0 | G41: =MAX(0,G22-Assumptions!C73)/1000000*Assumptions!C69+MAX(0,G22*(Assumptions!C71/1000)*(Assumptions!C72/1024)-Assumptions!C74)*Assumptions!C70 -> 0 | H41: =MAX(0,H22-Assumptions!C73)/1000000*Assumptions!C69+MAX(0,H22*(Assumptions!C71/1000)*(Assumptions!C72/1024)-Assumptions!C74)*Assumptions!C70 -> 0 | I41: =MAX(0,I22-Assumptions!C73)/1000000*Assumptions!C69+MAX(0,I22*(Assumptions!C71/1000)*(Assumptions!C72/1024)-Assumptions!C74)*Assumptions!C70 -> 0 | J41: =MAX(0,J22-Assumptions!C73)/1000000*Assumptions!C69+MAX(0,J22*(Assumptions!C71/1000)*(Assumptions!C72/1024)-Assumptions!C74)*Assumptions!C70 -> 0 | K41: =MAX(0,K22-Assumptions!C73)/1000000*Assumptions!C69+MAX(0,K22*(Assumptions!C71/1000)*(Assumptions!C72/1024)-Assumptions!C74)*Assumptions!C70 -> 0 | L41: =MAX(0,L22-Assumptions!C73)/1000000*Assumptions!C69+MAX(0,L22*(Assumptions!C71/1000)*(Assumptions!C72/1024)-Assumptions!C74)*Assumptions!C70 -> 0 | M41: =MAX(0,M22-Assumptions!C73)/1000000*Assumptions!C69+MAX(0,M22*(Assumptions!C71/1000)*(Assumptions!C72/1024)-Assumptions!C74)*Assumptions!C70 -> 0 | N41: =MAX(0,N22-Assumptions!C73)/1000000*Assumptions!C69+MAX(0,N22*(Assumptions!C71/1000)*(Assumptions!C72/1024)-Assumptions!C74)*Assumptions!C70 -> 0 | O41: =MAX(0,O22-Assumptions!C73)/1000000*Assumptions!C69+MAX(0,O22*(Assumptions!C71/1000)*(Assumptions!C72/1024)-Assumptions!C74)*Assumptions!C70 -> 0 | P41: =MAX(0,P22-Assumptions!C73)/1000000*Assumptions!C69+MAX(0,P22*(Assumptions!C71/1000)*(Assumptions!C72/1024)-Assumptions!C74)*Assumptions!C70 -> 0 | Q41: =MAX(0,Q22-Assumptions!C73)/1000000*Assumptions!C69+MAX(0,Q22*(Assumptions!C71/1000)*(Assumptions!C72/1024)-Assumptions!C74)*Assumptions!C70 -> 0 | R41: =MAX(0,R22-Assumptions!C73)/1000000*Assumptions!C69+MAX(0,R22*(Assumptions!C71/1000)*(Assumptions!C72/1024)-Assumptions!C74)*Assumptions!C70 -> 0 | S41: =MAX(0,S22-Assumptions!C73)/1000000*Assumptions!C69+MAX(0,S22*(Assumptions!C71/1000)*(Assumptions!C72/1024)-Assumptions!C74)*Assumptions!C70 -> 0 | T41: =MAX(0,T22-Assumptions!C73)/1000000*Assumptions!C69+MAX(0,T22*(Assumptions!C71/1000)*(Assumptions!C72/1024)-Assumptions!C74)*Assumptions!C70 -> 0 | U41: =MAX(0,U22-Assumptions!C73)/1000000*Assumptions!C69+MAX(0,U22*(Assumptions!C71/1000)*(Assumptions!C72/1024)-Assumptions!C74)*Assumptions!C70 -> 0 | V41: =MAX(0,V22-Assumptions!C73)/1000000*Assumptions!C69+MAX(0,V22*(Assumptions!C71/1000)*(Assumptions!C72/1024)-Assumptions!C74)*Assumptions!C70 -> 0 | W41: =MAX(0,W22-Assumptions!C73)/1000000*Assumptions!C69+MAX(0,W22*(Assumptions!C71/1000)*(Assumptions!C72/1024)-Assumptions!C74)*Assumptions!C70 -> 0 | X41: =MAX(0,X22-Assumptions!C73)/1000000*Assumptions!C69+MAX(0,X22*(Assumptions!C71/1000)*(Assumptions!C72/1024)-Assumptions!C74)*Assumptions!C70 -> 0 | Y41: =MAX(0,Y22-Assumptions!C73)/1000000*Assumptions!C69+MAX(0,Y22*(Assumptions!C71/1000)*(Assumptions!C72/1024)-Assumptions!C74)*Assumptions!C70 -> 0 | Z41: =MAX(0,Z22-Assumptions!C73)/1000000*Assumptions!C69+MAX(0,Z22*(Assumptions!C71/1000)*(Assumptions!C72/1024)-Assumptions!C74)*Assumptions!C70 -> 0
B42: Other Platform (CIAM + DNS + Monitoring) | C42: =Assumptions!C78+MAX(0,C11*0.3-50000)*Assumptions!C79+Assumptions!C80+Assumptions!C81 -> 25 | D42: =Assumptions!C78+MAX(0,D11*0.3-50000)*Assumptions!C79+Assumptions!C80+Assumptions!C81 -> 25 | E42: =Assumptions!C78+MAX(0,E11*0.3-50000)*Assumptions!C79+Assumptions!C80+Assumptions!C81 -> 25 | F42: =Assumptions!C78+MAX(0,F11*0.3-50000)*Assumptions!C79+Assumptions!C80+Assumptions!C81 -> 25 | G42: =Assumptions!C78+MAX(0,G11*0.3-50000)*Assumptions!C79+Assumptions!C80+Assumptions!C81 -> 25 | H42: =Assumptions!C78+MAX(0,H11*0.3-50000)*Assumptions!C79+Assumptions!C80+Assumptions!C81 -> 25 | I42: =Assumptions!C78+MAX(0,I11*0.3-50000)*Assumptions!C79+Assumptions!C80+Assumptions!C81 -> 25 | J42: =Assumptions!C78+MAX(0,J11*0.3-50000)*Assumptions!C79+Assumptions!C80+Assumptions!C81 -> 25 | K42: =Assumptions!C78+MAX(0,K11*0.3-50000)*Assumptions!C79+Assumptions!C80+Assumptions!C81 -> 25 | L42: =Assumptions!C78+MAX(0,L11*0.3-50000)*Assumptions!C79+Assumptions!C80+Assumptions!C81 -> 25 | M42: =Assumptions!C78+MAX(0,M11*0.3-50000)*Assumptions!C79+Assumptions!C80+Assumptions!C81 -> 25 | N42: =Assumptions!C78+MAX(0,N11*0.3-50000)*Assumptions!C79+Assumptions!C80+Assumptions!C81 -> 25 | O42: =Assumptions!C78+MAX(0,O11*0.3-50000)*Assumptions!C79+Assumptions!C80+Assumptions!C81 -> 25 | P42: =Assumptions!C78+MAX(0,P11*0.3-50000)*Assumptions!C79+Assumptions!C80+Assumptions!C81 -> 25 | Q42: =Assumptions!C78+MAX(0,Q11*0.3-50000)*Assumptions!C79+Assumptions!C80+Assumptions!C81 -> 25 | R42: =Assumptions!C78+MAX(0,R11*0.3-50000)*Assumptions!C79+Assumptions!C80+Assumptions!C81 -> 25 | S42: =Assumptions!C78+MAX(0,S11*0.3-50000)*Assumptions!C79+Assumptions!C80+Assumptions!C81 -> 25 | T42: =Assumptions!C78+MAX(0,T11*0.3-50000)*Assumptions!C79+Assumptions!C80+Assumptions!C81 -> 25 | U42: =Assumptions!C78+MAX(0,U11*0.3-50000)*Assumptions!C79+Assumptions!C80+Assumptions!C81 -> 25 | V42: =Assumptions!C78+MAX(0,V11*0.3-50000)*Assumptions!C79+Assumptions!C80+Assumptions!C81 -> 25 | W42: =Assumptions!C78+MAX(0,W11*0.3-50000)*Assumptions!C79+Assumptions!C80+Assumptions!C81 -> 25 | X42: =Assumptions!C78+MAX(0,X11*0.3-50000)*Assumptions!C79+Assumptions!C80+Assumptions!C81 -> 25 | Y42: =Assumptions!C78+MAX(0,Y11*0.3-50000)*Assumptions!C79+Assumptions!C80+Assumptions!C81 -> 25 | Z42: =Assumptions!C78+MAX(0,Z11*0.3-50000)*Assumptions!C79+Assumptions!C80+Assumptions!C81 -> 25
B43: TOTAL INFRASTRUCTURE | C43: =C35+C39+C40+C41+C42 -> 25.058617 | D43: =D35+D39+D40+D41+D42 -> 25.119254 | E43: =E35+E39+E40+E41+E42 -> 25.263275 | F43: =F35+F39+F40+F41+F42 -> 25.416618 | G43: =G35+G39+G40+G41+G42 -> 25.585298 | H43: =H35+H39+H40+H41+H42 -> 25.76903 | I43: =I35+I39+I40+I41+I42 -> 25.969239 | J43: =J35+J39+J40+J41+J42 -> 26.188239 | ... Z43: =Z35+Z39+Z40+Z41+Z42 -> 34.175278
B45: REVENUE
...

Sheet Annual Summary
B1: MemoryCharm — Annual Summary
C3: Year 1 (M1-12) | D3: Year 2 (M13-24) | E3: Total (24 Mo)
B5: Total Charms Sold | C5: =SUM('24-Month Projections'!C9:N9) -> 3122 | D5: =SUM('24-Month Projections'!O9:Z9) -> 8913 | E5: =C5+D5 -> 12035
B6: Cumulative Charms (End) | C6: ='24-Month Projections'!N10 -> 3122 | D6: ='24-Month Projections'!Z10 -> 12035 | E6: =D6 -> 12035
B7: Active Charms (End) | C7: ='24-Month Projections'!N11 -> 2654 | D7: ='24-Month Projections'!Z11 -> 10230 | E7: =D7 -> 10230
B8: Total Storage (GB, end of period) | C8: ='24-Month Projections'!N15 -> 93.54 | D8: ='24-Month Projections'!Z15 -> 360.62 | E8: =D8 -> 360.62
B10: Total Revenue | C10: =SUM('24-Month Projections'!C52:N52) -> 132013.99 | D10: =SUM('24-Month Projections'!O52:Z52) -> 414546.66 | E10: =C10+D10 -> 546560.65
B11: Charm Revenue | C11: =SUM('24-Month Projections'!C46:N46)+SUM('24-Month Projections'!C47:N47)+SUM('24-Month Projections'!C48:N48) -> 121163.78 | D11: =SUM('24-Month Projections'!O46:Z46)+SUM('24-Month Projections'!O47:Z47)+SUM('24-Month Projections'!O48:Z48) -> 364830.87 | E11: =C11+D11 -> 485994.65
B12: Upsell Revenue | C12: =SUM('24-Month Projections'!C49:N49)+SUM('24-Month Projections'!C50:N50)+SUM('24-Month Projections'!C51:N51) -> 10850.21 | D12: =SUM('24-Month Projections'!O49:Z49)+SUM('24-Month Projections'!O50:Z50)+SUM('24-Month Projections'!O51:Z51) -> 49715.79 | E12: =C12+D12 -> 60566
B14: Total COGS | C14: =SUM('24-Month Projections'!C59:N59) -> 27849.5 | D14: =SUM('24-Month Projections'!O59:Z59) -> 80640.5 | E14: =C14+D14 -> 108490
B15: Gross Profit | C15: =SUM('24-Month Projections'!C60:N60) -> 104164.49 | D15: =SUM('24-Month Projections'!O60:Z60) -> 333906.16 | E15: =C15+D15 -> 438070.65
B16: Gross Margin % | C16: =IF(C10>0,C15/C10,0) -> 0.7890413 | D16: =IF(D10>0,D15/D10,0) -> 0.80547304 | E16: =IF(E10>0,E15/E10,0) -> 0.80150419
B18: Total Operating Expenses | C18: =SUM('24-Month Projections'!C70:N70) -> 27666.147 | D18: =SUM('24-Month Projections'!O70:Z70) -> 63744.408 | E18: =C18+D18 -> 91410.555
B19: Infrastructure | C19: =SUM('24-Month Projections'!C43:N43) -> 311.74137 | D19: =SUM('24-Month Projections'!O43:Z43) -> 365.05441 | E19: =C19+D19 -> 676.79578
B20: Azure Blob Storage | C20: =SUM('24-Month Projections'!C35:N35) -> 5.7491534 | D20: =SUM('24-Month Projections'!O35:Z35) -> 28.077408 | E20: =C20+D20 -> 33.826562
B21: Cloudflare R2 | C21: =SUM('24-Month Projections'!C39:N39) -> 5.97945 | D21: =SUM('24-Month Projections'!O39:Z39) -> 36.92835 | E21: =C21+D21 -> 42.9078
B22: Azure Table Storage | C22: =SUM('24-Month Projections'!C40:N40) -> 0.012764217 | D22: =SUM('24-Month Projections'!O40:Z40) -> 0.048652211 | E22: =C22+D22 -> 0.061416428
B23: Azure Functions | C23: =SUM('24-Month Projections'!C41:N41) -> 0 | D23: =SUM('24-Month Projections'!O41:Z41) -> 0 | E23: =C23+D23 -> 0
B24: Other Platform | C24: =SUM('24-Month Projections'!C42:N42) -> 300 | D24: =SUM('24-Month Projections'!O42:Z42) -> 300 | E24: =C24+D24 -> 600
B25: Marketing | C25: =SUM('24-Month Projections'!C65:N65) -> 7961 | D25: =SUM('24-Month Projections'!O65:Z65) -> 14309 | E25: =C25+D25 -> 22270
B26: Shipping | C26: =SUM('24-Month Projections'!C66:N66) -> 10927 | D26: =SUM('24-Month Projections'!O66:Z66) -> 31195.5 | E26: =C26+D26 -> 42122.5
B27: Payment Processing | C27: =SUM('24-Month Projections'!C67:N67) -> 3828.4057 | D27: =SUM('24-Month Projections'!O67:Z67) -> 12021.853 | E27: =C27+D27 -> 15850.259
B28: Support + Legal | C28: =SUM('24-Month Projections'!C68:N68)+SUM('24-Month Projections'!C69:N69) -> 4638 | D28: =SUM('24-Month Projections'!O68:Z68)+SUM('24-Month Projections'!O69:Z69) -> 5853 | E28: =C28+D28 -> 10491
B30: EBITDA | C30: =SUM('24-Month Projections'!C73:N73) -> 76498.343 | D30: =SUM('24-Month Projections'!O73:Z73) -> 270161.75 | E30: =C30+D30 -> 346660.1
B31: EBITDA Margin % | C31: =IF(C10>0,C30/C10,0) -> 0.57947149 | D31: =IF(D10>0,D30/D10,0) -> 0.65170409 | E31: =IF(E10>0,E30/E10,0) -> 0.63425732
B32: Tax | C32: =SUM('24-Month Projections'!C75:N75) -> 16064.652 | D32: =SUM('24-Month Projections'!O75:Z75) -> 56733.968 | E32: =C32+D32 -> 72798.62
B33: NET INCOME | C33: =SUM('24-Month Projections'!C76:N76) -> 60433.691 | D33: =SUM('24-Month Projections'!O76:Z76) -> 213427.78 | E33: =C33+D33 -> 273861.48
B35: RETURNS & REPLACEMENTS
B36: Returned Units | C36: =SUM('24-Month Projections'!C88:N88) -> 187 | D36: =SUM('24-Month Projections'!O88:Z88) -> 534 | E36: =C36+D36 -> 721
B37: Replacement Units | C37: =SUM('24-Month Projections'!C91:N91) -> 94 | D37: =SUM('24-Month Projections'!O91:Z91) -> 268 | E37: =C37+D37 -> 362
B38: Total Return & Replacement Cost | C38: =SUM('24-Month Projections'!C101:N101) -> 10270.93 | D38: =SUM('24-Month Projections'!O101:Z101) -> 31556.7 | E38: =C38+D38 -> 41827.63
B39: Margin Erosion % | C39: =IF(C10>0,C38/C10,0) -> 0.07780183 | D39: =IF(D10>0,D38/D10,0) -> 0.076123398 | E39: =IF(E10>0,E38/E10,0) -> 0.0765288
B41: ADJUSTED P&L (After Returns)
B42: Net Revenue | C42: =SUM('24-Month Projections'!C104:N104) -> 124105.32 | D42: =SUM('24-Month Projections'!O104:Z104) -> 389710.74 | E42: =C42+D42 -> 513816.06
B43: Adjusted COGS | C43: =SUM('24-Month Projections'!C105:N105) -> 28573.759 | D43: =SUM('24-Month Projections'!O105:Z105) -> 82685.277 | E43: =C43+D43 -> 111259.04
B44: Adjusted Gross Profit | C44: =SUM('24-Month Projections'!C107:N107) -> 93893.56 | D44: =SUM('24-Month Projections'!O107:Z107) -> 302349.46 | E44: =C44+D44 -> 396243.02
B45: Adjusted Gross Margin % | C45: =IF(C42>0,C44/C42,0) -> 0.75656354 | D45: =IF(D42>0,D44/D42,0) -> 0.77583046 | E45: =IF(E42>0,E44/E42,0) -> 0.7711768
B46: Adjusted EBITDA | C46: =SUM('24-Month Projections'!C109:N109) -> 66227.413 | D46: =SUM('24-Month Projections'!O109:Z109) -> 238605.05 | E46: =C46+D46 -> 304832.46
B47: Adjusted EBITDA Margin % | C47: =IF(C42>0,C46/C42,0) -> 0.53363879 | D47: =IF(D42>0,D46/D42,0) -> 0.61226194 | E47: =IF(E42>0,E46/E42,0) -> 0.59327158
B48: ADJUSTED NET INCOME | C48: =SUM('24-Month Projections'!C111:N111) -> 52319.656 | D48: =SUM('24-Month Projections'!O111:Z111) -> 188497.99 | E48: =C48+D48 -> 240817.65

Sheet Scenario Notes
B1: Scenario Playbook
B2: Copy the workbook, change Assumptions, compare results
B4: Assumption | C4: Conservative | D4: Base Case | E4: Optimistic
B5: 10-Year Charm Price | C5: $24.99 | D5: $29.99 | E5: $34.99
B6: 15-Year Charm Price | C6: $39.99 | D6: $44.99 | E6: $54.99
B7: Perpetual Charm Price | C7: $59.99 | D7: $69.99 | E7: $89.99
B8: Starting 10-Year Units/Mo | C8: 50 | D8: 100 | E8: 200
B9: Starting 15-Year Units/Mo | C9: 20 | D9: 40 | E9: 80
B10: Starting Perpetual Units/Mo | C10: 5 | D10: 15 | E10: 30
B11: MoM Growth (10-Year) | C11: 5% | D11: 8% | E11: 12%
B12: MoM Growth (15-Year) | C12: 6% | D12: 10% | E12: 15%
B13: MoM Growth (Perpetual) | C13: 8% | D13: 12% | E13: 18%
B14: COGS per Charm | C14: $10.00 | D14: $8.50 | E14: $7.00
B15: Avg Content Size (MB) | C15: 20 | D15: 35.9 | E15: 60
... B21: Gift Wrap Attach Rate | C21: 8% | D21: 15% | E21: 25%
B23: HOW TO USE:
B24: 1. Base Case values match the Assumptions sheet defaults
B25: 2. Go to Assumptions sheet and change the yellow cells
B26: 3. Projections and Annual Summary auto-update
B27: 4. File > Save As to create copies for each scenario
B28: 5. Key infrastructure levers: content size, views/charm, video mix %

Sheet Per-Charm Costs
B1: Per-Charm Hosting Cost Breakdown (No Free Tier)
B2: What it costs to host ONE charm — raw service rates, no free tier credits applied
B3: All values linked to Assumptions sheet — change inputs there to update these costs
B5: SINGLE CHARM PROFILE
B6: Metric | C6: Value | D6: Unit
B7: Content size (weighted avg) | C7: =Assumptions!C33 -> 36.1 | D7: MB | F7: From Assumptions: video/image/audio weighted mix
B8: Content size in GB | C8: =C7/1024 -> 0.035253906 | D8: GB
B9: Views per month (first 3 months — novelty) | C9: =Assumptions!C38 -> 8 | D9: views/month
B10: Views per month (after 3 months — long-tail) | C10: =Assumptions!C39 -> 2 | D10: views/month
B11: Blended avg views/month (assuming mostly long-tail) | C11: =ROUND((C9*3+C10*9)/12,1) -> 3.5 | D11: views/month | F11: Year-weighted: 3 months novelty + 9 months long-tail
B12: % of views requiring glyph verification | C12: =Assumptions!C40 -> 0.4
B13: API calls per view (GetCharm + glyph if needed) | C13: =1+C12 -> 1.4 | F13: 1 GetCharm call per view + glyph verify probability
B14: Table reads per view | C14: =Assumptions!C43 -> 3
B15: Table writes per view (glyph attempts + rate-limit log) | C15: =ROUND(C12*2+0.1,1) -> 0.9 | F15: 2 writes per glyph verify + 10% sampled request logging
B17: ONE-TIME SETUP COSTS (per charm — claim through finalize)
B18: Service / Operation | C18: Cost | D18: Calculation | E18: Notes
B19: Azure Functions: Lifecycle API Calls | C19: =(Assumptions!C41/1000000)*Assumptions!C69 + Assumptions!C41*(Assumptions!C71/1000)*(Assumptions!C72/1024)*Assumptions!C70 -> 3e-06 | D19: 5 calls x exec + compute cost | F19: claim + configure + get-upload-urls + finalize + preview
B20: Cloudflare R2: Upload Writes (Class A) | C20: =(2*(1+Assumptions!C35)/1000000)*Assumptions!C56 -> 1.08e-05 | D20: 2 PUT ops x (1+re-upload rate) | F20: PUT blob + list verify; re-uploads during 14-day settling
B21: Azure Blob: Backup Upload Writes | C21: =(2*(1+Assumptions!C35)/10000)*Assumptions!C48 -> 2.4e-05 | D21: 2 ops x (1+re-upload rate) / 10K
B22: Azure Table: Setup Entity Writes | C22: =(Assumptions!C42/10000)*Assumptions!C64 -> 2.88e-07 | D22: 8 writes / 10K x txn rate | F22: charm + user-charm + profile + request log entities
B23: Azure Table: Entity Storage (first month) | C23: =(Assumptions!C65/1024/1024)*Assumptions!C63 -> 8.5830688e-08 | D23: ~2 KB entity / GB x rate
B24: TOTAL ONE-TIME SETUP COST | C24: =SUM(C19:C23) -> 3.8173831e-05
B26: MONTHLY ONGOING COSTS (per charm — storage + playback) | F26: Assumes blended avg views/month from row 11
B27: Service / Operation | C27: $/Month | D27: Calculation | E27: Notes
B28: CLOUDFLARE R2
B29: R2: Storage (content GB x rate) | C29: =C8*Assumptions!C55 -> 0.00052880859 | D29: GB x $0.015/GB/mo
B30: R2: Class B Reads — playback downloads | C30: =(C11/1000000)*Assumptions!C57 -> 1.26e-06 | D30: views/mo / 1M x rate | F30: Every view = 1 GET from R2
B31: R2: Egress / Bandwidth | C31: =C11*C8*Assumptions!C58 -> 0 | D31: $0.00 — zero egress | F31: Cloudflare's key advantage: zero bandwidth cost
B32: R2 SUBTOTAL | C32: =C29+C30+C31 -> 0.00053006859
B34: AZURE BLOB STORAGE — COOL TIER
B35: Azure Blob: Storage (backup mirror — same GB) | C35: =C8*Assumptions!C47 -> 0.00035253906 | D35: GB x $0.01/GB/mo
B36: Azure Blob: Read Ops (fallback — 2% of views) | C36: =(C11*0.02/10000)*Assumptions!C49 -> 7e-08 | D36: 2% fallback reads | F36: Only when R2 is unavailable; client falls back to Azure
B37: Azure Blob: Data Retrieval (cool tier penalty) | C37: =C11*0.02*C8*Assumptions!C50 -> 2.4677734e-05 | D37: 2% fallback x GB x retrieval rate | F37: Cool tier charges per-GB on read; hot tier does not
B38: Azure Blob: Egress (fallback downloads) | C38: =C11*0.02*C8*Assumptions!C51 -> 0.00021469629 | D38: 2% fallback x GB x egress rate | F38: $0.087/GB — only on Azure-direct downloads
B39: Azure Blob SUBTOTAL | C39: =C35+C36+C37+C38 -> 0.00059198309
B41: AZURE TABLE STORAGE
B42: Table: Entity Storage (ongoing) | C42: =(Assumptions!C65/1024/1024)*Assumptions!C63 -> 8.5830688e-08 | D42: ~2 KB entity set / month
B43: Table: Read Transactions (views x reads/view) | C43: =(C11*C14/10000)*Assumptions!C64 -> 3.78e-07 | D43: views x 3 reads / 10K x rate
B44: Table: Write Transactions (glyph + logging) | C44: =(C11*C15/10000)*Assumptions!C64 -> 1.134e-07 | D44: views x writes/view / 10K x rate
B45: Azure Table SUBTOTAL | C45: =C42+C43+C44 -> 5.7723069e-07
...

Sheet Revenue Recognition
B1: Revenue Recognition — Cash vs Hybrid vs Straight-Line
B2: Compares when revenue is recognized under each method + deferred revenue liability
C4: Month 1 | D4: Month 2 | E4: Month 3 | F4: Month 4 | G4: Month 5 | H4: Month 6 | I4: Month 7 | J4: Month 8 | K4: Month 9 | L4: Month 10 | M4: Month 11 | N4: Month 12 | O4: Month 13 | P4: Month 14 | Q4: Month 15 | R4: Month 16 | S4: Month 17 | T4: Month 18 | U4: Month 19 | V4: Month 20 | W4: Month 21 | X4: Month 22 | Y4: Month 23 | Z4: Month 24
B6: PER-CHARM REVENUE SPLIT — HYBRID METHOD | C6: 10-Year | D6: 15-Year | E6: Perpetual | F6: Lifetime months: | G6: 120 | H6: 180 | I6: 360
B7: Sale Price | C7: =Assumptions!C6 -> 29.99 | D7: =Assumptions!C7 -> 44.99 | E7: =Assumptions!C8 -> 69.99
B8: Upfront Costs (COGS + ship + processing + setup) | C8: =Assumptions!D6+Assumptions!C86+C7*Assumptions!C87+'Per-Charm Costs'!C24 -> 12.869748 | D8: =Assumptions!D7+Assumptions!C86+D7*Assumptions!C87+'Per-Charm Costs'!C24 -> 13.304748 | E8: =Assumptions!D8+Assumptions!C86+E7*Assumptions!C87+'Per-Charm Costs'!C24 -> 14.529748
B9: Hybrid: Revenue Recognized at Sale | C9: =C8 -> 12.869748 | D9: =D8 -> 13.304748 | E9: =E8 -> 14.529748 | F9: Covers COGS + fulfillment + payment fee + setup hosting
B10: Hybrid: Deferred Revenue (to escrow) | C10: =C7-C9 -> 17.120252 | D10: =D7-D9 -> 31.685252 | E10: =E7-E9 -> 55.460252 | F10: Goes to escrow / deferred revenue liability on balance sheet
B11: Hybrid: Monthly Recognition from Deferred | C11: =C10/G6 -> 0.14266877 | D11: =D10/H6 -> 0.17602918 | E11: =E10/I6 -> 0.15405626 | F11: Deferred portion ÷ lifetime months
B12: Straight-Line: Monthly Recognition (all deferred) | C12: =C7/G6 -> 0.24991667 | D12: =D7/H6 -> 0.24994444 | E12: =E7/I6 -> 0.19441667 | F12: Full price ÷ lifetime months — most conservative
B14: CASH COLLECTED (Point of Sale)
B15: 10-Year Charms — Cumulative Sold | C15: ='24-Month Projections'!C6 -> 100 | D15: =C15+'24-Month Projections'!D6 -> 208 | E15: =D15+'24-Month Projections'!E6 -> 325 | F15: =E15+'24-Month Projections'!F6 -> 451 | G15: =F15+'24-Month Projections'!G6 -> 587 | H15: =G15+'24-Month Projections'!H6 -> 734 | I15: =H15+'24-Month Projections'!I6 -> 893 | J15: =I15+'24-Month Projections'!J6 -> 1065 | K15: =J15+'24-Month Projections'!K6 -> 1251 | ... Z15: =Y15+'24-Month Projections'!Z6 -> 6719
B16: 15-Year Charms — Cumulative Sold | C16: ='24-Month Projections'!C7 -> 40 | D16: =C16+'24-Month Projections'!D7 -> 84 | E16: =D16+'24-Month Projections'!E7 -> 132 | F16: =E16+'24-Month Projections'!F7 -> 185 | G16: =F16+'24-Month Projections'!G7 -> 243 | H16: =G16+'24-Month Projections'!H7 -> 307 | I16: =H16+'24-Month Projections'!I7 -> 377 | J16: =I16+'24-Month Projections'!J7 -> 454 | K16: =J16+'24-Month Projections'!K7 -> 539 | ... Z16: =Y16+'24-Month Projections'!Z7 -> 3503
B17: Perpetual Charms — Cumulative Sold | C17: ='24-Month Projections'!C8 -> 15 | D17: =C17+'24-Month Projections'!D8 -> 32 | E17: =D17+'24-Month Projections'!E8 -> 51 | F17: =E17+'24-Month Projections'!F8 -> 72 | G17: =F17+'24-Month Projections'!G8 -> 96 | H17: =G17+'24-Month Projections'!H8 -> 123 | I17: =H17+'24-Month Projections'!I8 -> 153 | J17: =I17+'24-Month Projections'!J8 -> 187 | K17: =J17+'24-Month Projections'!K8 -> 225 | ... Z17: =Y17+'24-Month Projections'!Z8 -> 1813
B18: Charm Cash Collected (month) | C18: ='24-Month Projections'!C6*$C$7+'24-Month Projections'!C7*$D$7+'24-Month Projections'!C8*$E$7 -> 5848.45 | D18: ='24-Month Projections'!D6*$C$7+'24-Month Projections'!D7*$D$7+'24-Month Projections'!D8*$E$7 -> 6408.31 | E18: ='24-Month Projections'!E6*$C$7+'24-Month Projections'!E7*$D$7+'24-Month Projections'!E8*$E$7 -> 6998.16 | F18: ='24-Month Projections'!F6*$C$7+'24-Month Projections'!F7*$D$7+'24-Month Projections'!F8*$E$7 -> 7633 | G18: ='24-Month Projections'!G6*$C$7+'24-Month Projections'!G7*$D$7+'24-Month Projections'!G8*$E$7 -> 8367.82 | H18: ='24-Month Projections'!H6*$C$7+'24-Month Projections'!H7*$D$7+'24-Month Projections'!H8*$E$7 -> 9177.62 | I18: ='24-Month Projections'!I6*$C$7+'24-Month Projections'!I7*$D$7+'24-Month Projections'!I8*$E$7 -> 10017.41 | J18: ='24-Month Projections'!J6*$C$7+'24-Month Projections'!J7*$D$7+'24-Month Projections'!J8*$E$7 -> 11002.17 | ... Z18: ='24-Month Projections'!Z6*$C$7+'24-Month Projections'!Z7*$D$7+'24-Month Projections'!Z8*$E$7 -> 48268.45
B19: Upsell Cash Collected (recognized immediately) | C19: ='24-Month Projections'!C49+'24-Month Projections'!C50+'24-Month Projections'!C51 -> 199.72 | D19: ='24-Month Projections'!D49+'24-Month Projections'!D50+'24-Month Projections'!D51 -> 274.66 | E19: ='24-Month Projections'!E49+'24-Month Projections'!E50+'24-Month Projections'!E51 -> 389.57 | F19: ='24-Month Projections'!F49+'24-Month Projections'!F50+'24-Month Projections'!F51 -> 499.49 | G19: ='24-Month Projections'!G49+'24-Month Projections'!G50+'24-Month Projections'!G51 -> 629.39 | H19: ='24-Month Projections'!H49+'24-Month Projections'!H50+'24-Month Projections'!H51 -> 764.29 | I19: ='24-Month Projections'!I49+'24-Month Projections'!I50+'24-Month Projections'!I51 -> 894.19 | J19: ='24-Month Projections'!J49+'24-Month Projections'!J50+'24-Month Projections'!J51 -> 1059.07 | ... Z19: ='24-Month Projections'!Z49+'24-Month Projections'!Z50+'24-Month Projections'!Z51 -> 6874.66
B20: TOTAL CASH COLLECTED | C20: =C18+C19 -> 6048.17 | D20: =D18+D19 -> 6682.97 | E20: =E18+E19 -> 7387.73 | F20: =F18+F19 -> 8132.49 | G20: =G18+G19 -> 8997.21 | H20: =H18+H19 -> 9941.91 | I20: =I18+I19 -> 10911.6 | J20: =J18+J19 -> 12061.24 | ... Z20: =Z18+Z19 -> 55143.11
B22: HYBRID METHOD — Recognized Revenue | F22: COGS portion at sale + deferred over lifetime
B23: Upfront Recognition (new sales x upfront portion) | C23: ='24-Month Projections'!C6*$C$9+'24-Month Projections'!C7*$D$9+'24-Month Projections'!C8*$E$9 -> 2037.111 | D23: ='24-Month Projections'!D6*$C$9+'24-Month Projections'!D7*$D$9+'24-Month Projections'!D8*$E$9 -> 2222.3474 | E23: ='24-Month Projections'!E6*$C$9+'24-Month Projections'!E7*$D$9+'24-Month Projections'!E8*$E$9 -> 2420.4537 | F23: ='24-Month Projections'!F6*$C$9+'24-Month Projections'!F7*$D$9+'24-Month Projections'!F8*$E$9 -> 2631.8646 | G23: ='24-Month Projections'!G6*$C$9+'24-Month Projections'!G7*$D$9+'24-Month Projections'!G8*$E$9 -> 2870.6751 | H23: ='24-Month Projections'!H6*$C$9+'24-Month Projections'!H7*$D$9+'24-Month Projections'!H8*$E$9 -> 3135.6601 | I23: ='24-Month Projections'!I6*$C$9+'24-Month Projections'!I7*$D$9+'24-Month Projections'!I8*$E$9 -> 3413.5148 | J23: ='24-Month Projections'!J6*$C$9+'24-Month Projections'!J7*$D$9+'24-Month Projections'!J8*$E$9 -> 3732.0737 | ... Z23: ='24-Month Projections'!Z6*$C$9+'24-Month Projections'!Z7*$D$9+'24-Month Projections'!Z8*$E$9 -> 15363.829
